{
  "uid" : "445ea2a75673ea9d",
  "name" : "User can't successfully log in with invalid username.",
  "fullName" : "tests.core_features.test_login.TestLogin#test_login_with_invalid_username",
  "historyId" : "d9da1d35f9d1a309fb04ddfe89a222bc",
  "time" : {
    "start" : 1705596717903,
    "stop" : 1705596719167,
    "duration" : 1264
  },
  "status" : "skipped",
  "statusMessage" : "XFAIL reason: Known server-side issue\n\n_pytest.outcomes.XFailed: Known server-side issue",
  "statusTrace" : "tests/core_features/test_login.py:69: in test_login_with_invalid_username\n    login_page.error_text.assert_error(\"The username and password could not be verified.\")\n        driver     = <selenium.webdriver.chrome.webdriver.WebDriver (session=\"98422d21be92c7b6dd8a1ec7c731ba15\")>\n        home_page  = <src.pages.home_page.HomePage object at 0x7f12d57a6290>\n        login_page = <src.pages.login_page.LoginPage object at 0x7f12d6f00350>\n        self       = <test_login.TestLogin object at 0x7f12d6af6850>\nsrc/base/base_element.py:71: in assert_error\n    pytest.xfail(reason=\"Known server-side issue\")\nE   _pytest.outcomes.XFailed: Known server-side issue\n        current_error = 'An internal error has occurred and has been logged.'\n        expected_error = 'The username and password could not be verified.'\n        self       = <src.base.base_element.BaseElement object at 0x7f12d6eb7310>\n        server_error = 'An internal error has occurred and has been logged.'",
  "flaky" : false,
  "newFailed" : false,
  "beforeStages" : [ {
    "name" : "Health check request",
    "time" : {
      "start" : 1705596635477,
      "stop" : 1705596636157,
      "duration" : 680
    },
    "status" : "passed",
    "steps" : [ ],
    "attachments" : [ ],
    "parameters" : [ ],
    "attachmentsCount" : 0,
    "shouldDisplayMessage" : false,
    "stepsCount" : 0,
    "hasContent" : false
  }, {
    "name" : "_session_faker",
    "time" : {
      "start" : 1705596635456,
      "stop" : 1705596635477,
      "duration" : 21
    },
    "status" : "passed",
    "steps" : [ ],
    "attachments" : [ ],
    "parameters" : [ ],
    "attachmentsCount" : 0,
    "shouldDisplayMessage" : false,
    "stepsCount" : 0,
    "hasContent" : false
  }, {
    "name" : "Initialize driver",
    "time" : {
      "start" : 1705596717066,
      "stop" : 1705596717902,
      "duration" : 836
    },
    "status" : "passed",
    "steps" : [ ],
    "attachments" : [ ],
    "parameters" : [ ],
    "attachmentsCount" : 0,
    "shouldDisplayMessage" : false,
    "stepsCount" : 0,
    "hasContent" : false
  } ],
  "testStage" : {
    "status" : "skipped",
    "statusMessage" : "XFAIL reason: Known server-side issue\n\n_pytest.outcomes.XFailed: Known server-side issue",
    "statusTrace" : "tests/core_features/test_login.py:69: in test_login_with_invalid_username\n    login_page.error_text.assert_error(\"The username and password could not be verified.\")\n        driver     = <selenium.webdriver.chrome.webdriver.WebDriver (session=\"98422d21be92c7b6dd8a1ec7c731ba15\")>\n        home_page  = <src.pages.home_page.HomePage object at 0x7f12d57a6290>\n        login_page = <src.pages.login_page.LoginPage object at 0x7f12d6f00350>\n        self       = <test_login.TestLogin object at 0x7f12d6af6850>\nsrc/base/base_element.py:71: in assert_error\n    pytest.xfail(reason=\"Known server-side issue\")\nE   _pytest.outcomes.XFailed: Known server-side issue\n        current_error = 'An internal error has occurred and has been logged.'\n        expected_error = 'The username and password could not be verified.'\n        self       = <src.base.base_element.BaseElement object at 0x7f12d6eb7310>\n        server_error = 'An internal error has occurred and has been logged.'",
    "steps" : [ {
      "name" : "Navigate to Home page",
      "time" : {
        "start" : 1705596717903,
        "stop" : 1705596718579,
        "duration" : 676
      },
      "status" : "passed",
      "steps" : [ ],
      "attachments" : [ ],
      "parameters" : [ ],
      "attachmentsCount" : 0,
      "shouldDisplayMessage" : false,
      "stepsCount" : 0,
      "hasContent" : false
    }, {
      "name" : "Fill in valid password, but invalid username",
      "time" : {
        "start" : 1705596718579,
        "stop" : 1705596718737,
        "duration" : 158
      },
      "status" : "passed",
      "steps" : [ ],
      "attachments" : [ ],
      "parameters" : [ ],
      "attachmentsCount" : 0,
      "shouldDisplayMessage" : false,
      "stepsCount" : 0,
      "hasContent" : false
    }, {
      "name" : "Log in",
      "time" : {
        "start" : 1705596718737,
        "stop" : 1705596719068,
        "duration" : 331
      },
      "status" : "passed",
      "steps" : [ ],
      "attachments" : [ ],
      "parameters" : [ ],
      "attachmentsCount" : 0,
      "shouldDisplayMessage" : false,
      "stepsCount" : 0,
      "hasContent" : false
    }, {
      "name" : "Check error message is displayed",
      "time" : {
        "start" : 1705596719068,
        "stop" : 1705596719167,
        "duration" : 99
      },
      "status" : "failed",
      "statusMessage" : "_pytest.outcomes.XFailed: Known server-side issue\n",
      "statusTrace" : "  File \"/usr/workspace/tests/core_features/test_login.py\", line 69, in test_login_with_invalid_username\n    login_page.error_text.assert_error(\"The username and password could not be verified.\")\n  File \"/usr/workspace/src/base/base_element.py\", line 71, in assert_error\n    pytest.xfail(reason=\"Known server-side issue\")\n  File \"/usr/local/lib/python3.11/site-packages/_pytest/outcomes.py\", line 256, in xfail\n    raise XFailed(reason)\n",
      "steps" : [ ],
      "attachments" : [ ],
      "parameters" : [ ],
      "attachmentsCount" : 0,
      "shouldDisplayMessage" : true,
      "stepsCount" : 0,
      "hasContent" : true
    } ],
    "attachments" : [ ],
    "parameters" : [ ],
    "attachmentsCount" : 0,
    "shouldDisplayMessage" : true,
    "stepsCount" : 4,
    "hasContent" : true
  },
  "afterStages" : [ {
    "name" : "Initialize driver::0",
    "time" : {
      "start" : 1705596719171,
      "stop" : 1705596719227,
      "duration" : 56
    },
    "status" : "passed",
    "steps" : [ {
      "name" : "Terminate driver",
      "time" : {
        "start" : 1705596719171,
        "stop" : 1705596719227,
        "duration" : 56
      },
      "status" : "passed",
      "steps" : [ ],
      "attachments" : [ ],
      "parameters" : [ ],
      "attachmentsCount" : 0,
      "shouldDisplayMessage" : false,
      "stepsCount" : 0,
      "hasContent" : false
    } ],
    "attachments" : [ ],
    "parameters" : [ ],
    "attachmentsCount" : 0,
    "shouldDisplayMessage" : false,
    "stepsCount" : 1,
    "hasContent" : true
  } ],
  "labels" : [ {
    "name" : "feature",
    "value" : "PARA-15261: User login"
  }, {
    "name" : "severity",
    "value" : "Minor"
  }, {
    "name" : "epic",
    "value" : "PARA-15240: User registration and authentication"
  }, {
    "name" : "parentSuite",
    "value" : "tests.core_features"
  }, {
    "name" : "suite",
    "value" : "test_login"
  }, {
    "name" : "subSuite",
    "value" : "TestLogin"
  }, {
    "name" : "host",
    "value" : "ea742366ae77"
  }, {
    "name" : "thread",
    "value" : "1-MainThread"
  }, {
    "name" : "framework",
    "value" : "pytest"
  }, {
    "name" : "language",
    "value" : "cpython3"
  }, {
    "name" : "package",
    "value" : "tests.core_features.test_login"
  }, {
    "name" : "resultFormat",
    "value" : "allure2"
  } ],
  "parameters" : [ ],
  "links" : [ ],
  "hidden" : false,
  "retry" : false,
  "extra" : {
    "severity" : "minor",
    "retries" : [ ],
    "categories" : [ ],
    "history" : {
      "statistic" : {
        "failed" : 0,
        "broken" : 1,
        "skipped" : 10,
        "passed" : 1,
        "unknown" : 0,
        "total" : 12
      },
      "items" : [ {
        "uid" : "7ef8df93fd53a64e",
        "status" : "skipped",
        "statusDetails" : "XFAIL reason: Known server-side issue\n\n_pytest.outcomes.XFailed: Known server-side issue",
        "time" : {
          "start" : 1705440554309,
          "stop" : 1705440555938,
          "duration" : 1629
        }
      }, {
        "uid" : "bc33de8f9dfa2785",
        "status" : "skipped",
        "statusDetails" : "XFAIL reason: Known server-side issue\n\n_pytest.outcomes.XFailed: Known server-side issue",
        "time" : {
          "start" : 1705392755010,
          "stop" : 1705392756929,
          "duration" : 1919
        }
      }, {
        "uid" : "f112a86e48f5a304",
        "status" : "broken",
        "statusDetails" : "selenium.common.exceptions.TimeoutException: Message:",
        "time" : {
          "start" : 1705147722132,
          "stop" : 1705147739232,
          "duration" : 17100
        }
      }, {
        "uid" : "2633b716cdc927f5",
        "status" : "passed",
        "time" : {
          "start" : 1705016482612,
          "stop" : 1705016483964,
          "duration" : 1352
        }
      }, {
        "uid" : "8b9cb9084df2ea16",
        "status" : "skipped",
        "statusDetails" : "XFAIL reason: Known server-side issue\n\n_pytest.outcomes.XFailed: Known server-side issue",
        "time" : {
          "start" : 1704913008756,
          "stop" : 1704913009802,
          "duration" : 1046
        }
      }, {
        "uid" : "82ed04e69ffff1b4",
        "status" : "skipped",
        "statusDetails" : "XFAIL reason: Health check failed with status code 502\n\n_pytest.outcomes.XFailed: Health check failed with status code 502",
        "time" : {
          "start" : 1704908682727,
          "stop" : 1704908682727,
          "duration" : 0
        }
      }, {
        "uid" : "4450358ad6895ac5",
        "status" : "skipped",
        "statusDetails" : "XFAIL reason: Known server-side issue\n\n_pytest.outcomes.XFailed: Known server-side issue",
        "time" : {
          "start" : 1704874972419,
          "stop" : 1704874973871,
          "duration" : 1452
        }
      }, {
        "uid" : "626f0d73e976d6c2",
        "status" : "skipped",
        "statusDetails" : "XFAIL reason: Known server-side issue\n\n_pytest.outcomes.XFailed: Known server-side issue",
        "time" : {
          "start" : 1704839546391,
          "stop" : 1704839547678,
          "duration" : 1287
        }
      }, {
        "uid" : "8b2995c1d1a4e4b5",
        "status" : "skipped",
        "statusDetails" : "XFAIL reason: Known server-side issue\n\n_pytest.outcomes.XFailed: Known server-side issue",
        "time" : {
          "start" : 1704789360100,
          "stop" : 1704789361271,
          "duration" : 1171
        }
      }, {
        "uid" : "e0e21325e73abf2c",
        "status" : "skipped",
        "statusDetails" : "XFAIL reason: Known server-side issue\n\n_pytest.outcomes.XFailed: Known server-side issue",
        "time" : {
          "start" : 1704759030280,
          "stop" : 1704759031332,
          "duration" : 1052
        }
      }, {
        "uid" : "5e4d1b792a3fc697",
        "status" : "skipped",
        "statusDetails" : "XFAIL reason: Known server-side issue\n\n_pytest.outcomes.XFailed: Known server-side issue",
        "time" : {
          "start" : 1704756570957,
          "stop" : 1704756572424,
          "duration" : 1467
        }
      } ]
    },
    "tags" : [ ]
  },
  "source" : "445ea2a75673ea9d.json",
  "parameterValues" : [ ]
}