{
  "uid" : "8b9cb9084df2ea16",
  "name" : "User can't successfully log in with invalid username.",
  "fullName" : "tests.core_features.test_login.TestLogin#test_login_with_invalid_username",
  "historyId" : "d9da1d35f9d1a309fb04ddfe89a222bc",
  "time" : {
    "start" : 1704913008756,
    "stop" : 1704913009802,
    "duration" : 1046
  },
  "status" : "skipped",
  "statusMessage" : "XFAIL reason: Known server-side issue\n\n_pytest.outcomes.XFailed: Known server-side issue",
  "statusTrace" : "tests/core_features/test_login.py:69: in test_login_with_invalid_username\n    login_page.error_text.assert_error(\"The username and password could not be verified.\")\n        driver     = <selenium.webdriver.chrome.webdriver.WebDriver (session=\"c1e639a9e216b83219b3651836514317\")>\n        home_page  = <src.pages.home_page.HomePage object at 0x7f3f58b3afd0>\n        login_page = <src.pages.login_page.LoginPage object at 0x7f3f58b3a5d0>\n        self       = <test_login.TestLogin object at 0x7f3f573df7d0>\nsrc/base/base_element.py:71: in assert_error\n    pytest.xfail(reason=\"Known server-side issue\")\nE   _pytest.outcomes.XFailed: Known server-side issue\n        current_error = 'An internal error has occurred and has been logged.'\n        expected_error = 'The username and password could not be verified.'\n        self       = <src.base.base_element.BaseElement object at 0x7f3f58b2d210>\n        server_error = 'An internal error has occurred and has been logged.'",
  "flaky" : false,
  "newFailed" : false,
  "beforeStages" : [ {
    "name" : "Initialize driver",
    "time" : {
      "start" : 1704913007916,
      "stop" : 1704913008756,
      "duration" : 840
    },
    "status" : "passed",
    "steps" : [ ],
    "attachments" : [ ],
    "parameters" : [ ],
    "attachmentsCount" : 0,
    "shouldDisplayMessage" : false,
    "stepsCount" : 0,
    "hasContent" : false
  }, {
    "name" : "_session_faker",
    "time" : {
      "start" : 1704912932040,
      "stop" : 1704912932061,
      "duration" : 21
    },
    "status" : "passed",
    "steps" : [ ],
    "attachments" : [ ],
    "parameters" : [ ],
    "attachmentsCount" : 0,
    "shouldDisplayMessage" : false,
    "stepsCount" : 0,
    "hasContent" : false
  }, {
    "name" : "Health check request",
    "time" : {
      "start" : 1704912932061,
      "stop" : 1704912932272,
      "duration" : 211
    },
    "status" : "passed",
    "steps" : [ ],
    "attachments" : [ ],
    "parameters" : [ ],
    "attachmentsCount" : 0,
    "shouldDisplayMessage" : false,
    "stepsCount" : 0,
    "hasContent" : false
  } ],
  "testStage" : {
    "status" : "skipped",
    "statusMessage" : "XFAIL reason: Known server-side issue\n\n_pytest.outcomes.XFailed: Known server-side issue",
    "statusTrace" : "tests/core_features/test_login.py:69: in test_login_with_invalid_username\n    login_page.error_text.assert_error(\"The username and password could not be verified.\")\n        driver     = <selenium.webdriver.chrome.webdriver.WebDriver (session=\"c1e639a9e216b83219b3651836514317\")>\n        home_page  = <src.pages.home_page.HomePage object at 0x7f3f58b3afd0>\n        login_page = <src.pages.login_page.LoginPage object at 0x7f3f58b3a5d0>\n        self       = <test_login.TestLogin object at 0x7f3f573df7d0>\nsrc/base/base_element.py:71: in assert_error\n    pytest.xfail(reason=\"Known server-side issue\")\nE   _pytest.outcomes.XFailed: Known server-side issue\n        current_error = 'An internal error has occurred and has been logged.'\n        expected_error = 'The username and password could not be verified.'\n        self       = <src.base.base_element.BaseElement object at 0x7f3f58b2d210>\n        server_error = 'An internal error has occurred and has been logged.'",
    "steps" : [ {
      "name" : "Navigate to Home page",
      "time" : {
        "start" : 1704913008756,
        "stop" : 1704913008977,
        "duration" : 221
      },
      "status" : "passed",
      "steps" : [ ],
      "attachments" : [ ],
      "parameters" : [ ],
      "attachmentsCount" : 0,
      "shouldDisplayMessage" : false,
      "stepsCount" : 0,
      "hasContent" : false
    }, {
      "name" : "Fill in valid password, but invalid username",
      "time" : {
        "start" : 1704913008978,
        "stop" : 1704913009143,
        "duration" : 165
      },
      "status" : "passed",
      "steps" : [ ],
      "attachments" : [ ],
      "parameters" : [ ],
      "attachmentsCount" : 0,
      "shouldDisplayMessage" : false,
      "stepsCount" : 0,
      "hasContent" : false
    }, {
      "name" : "Log in",
      "time" : {
        "start" : 1704913009143,
        "stop" : 1704913009715,
        "duration" : 572
      },
      "status" : "passed",
      "steps" : [ ],
      "attachments" : [ ],
      "parameters" : [ ],
      "attachmentsCount" : 0,
      "shouldDisplayMessage" : false,
      "stepsCount" : 0,
      "hasContent" : false
    }, {
      "name" : "Check error message is displayed",
      "time" : {
        "start" : 1704913009715,
        "stop" : 1704913009802,
        "duration" : 87
      },
      "status" : "failed",
      "statusMessage" : "_pytest.outcomes.XFailed: Known server-side issue\n",
      "statusTrace" : "  File \"/usr/workspace/tests/core_features/test_login.py\", line 69, in test_login_with_invalid_username\n    login_page.error_text.assert_error(\"The username and password could not be verified.\")\n  File \"/usr/workspace/src/base/base_element.py\", line 71, in assert_error\n    pytest.xfail(reason=\"Known server-side issue\")\n  File \"/usr/local/lib/python3.11/site-packages/_pytest/outcomes.py\", line 256, in xfail\n    raise XFailed(reason)\n",
      "steps" : [ ],
      "attachments" : [ ],
      "parameters" : [ ],
      "attachmentsCount" : 0,
      "shouldDisplayMessage" : true,
      "stepsCount" : 0,
      "hasContent" : true
    } ],
    "attachments" : [ ],
    "parameters" : [ ],
    "attachmentsCount" : 0,
    "shouldDisplayMessage" : true,
    "stepsCount" : 4,
    "hasContent" : true
  },
  "afterStages" : [ {
    "name" : "Initialize driver::0",
    "time" : {
      "start" : 1704913009806,
      "stop" : 1704913009862,
      "duration" : 56
    },
    "status" : "passed",
    "steps" : [ {
      "name" : "Terminate driver",
      "time" : {
        "start" : 1704913009806,
        "stop" : 1704913009862,
        "duration" : 56
      },
      "status" : "passed",
      "steps" : [ ],
      "attachments" : [ ],
      "parameters" : [ ],
      "attachmentsCount" : 0,
      "shouldDisplayMessage" : false,
      "stepsCount" : 0,
      "hasContent" : false
    } ],
    "attachments" : [ ],
    "parameters" : [ ],
    "attachmentsCount" : 0,
    "shouldDisplayMessage" : false,
    "stepsCount" : 1,
    "hasContent" : true
  } ],
  "labels" : [ {
    "name" : "epic",
    "value" : "PARA-15240: User registration and authentication"
  }, {
    "name" : "severity",
    "value" : "Minor"
  }, {
    "name" : "feature",
    "value" : "PARA-15261: User login"
  }, {
    "name" : "parentSuite",
    "value" : "tests.core_features"
  }, {
    "name" : "suite",
    "value" : "test_login"
  }, {
    "name" : "subSuite",
    "value" : "TestLogin"
  }, {
    "name" : "host",
    "value" : "eb65c548bdd0"
  }, {
    "name" : "thread",
    "value" : "1-MainThread"
  }, {
    "name" : "framework",
    "value" : "pytest"
  }, {
    "name" : "language",
    "value" : "cpython3"
  }, {
    "name" : "package",
    "value" : "tests.core_features.test_login"
  }, {
    "name" : "resultFormat",
    "value" : "allure2"
  } ],
  "parameters" : [ ],
  "links" : [ ],
  "hidden" : false,
  "retry" : false,
  "extra" : {
    "severity" : "minor",
    "retries" : [ ],
    "categories" : [ ],
    "history" : {
      "statistic" : {
        "failed" : 0,
        "broken" : 0,
        "skipped" : 7,
        "passed" : 0,
        "unknown" : 0,
        "total" : 7
      },
      "items" : [ {
        "uid" : "82ed04e69ffff1b4",
        "status" : "skipped",
        "statusDetails" : "XFAIL reason: Health check failed with status code 502\n\n_pytest.outcomes.XFailed: Health check failed with status code 502",
        "time" : {
          "start" : 1704908682727,
          "stop" : 1704908682727,
          "duration" : 0
        }
      }, {
        "uid" : "4450358ad6895ac5",
        "status" : "skipped",
        "statusDetails" : "XFAIL reason: Known server-side issue\n\n_pytest.outcomes.XFailed: Known server-side issue",
        "time" : {
          "start" : 1704874972419,
          "stop" : 1704874973871,
          "duration" : 1452
        }
      }, {
        "uid" : "626f0d73e976d6c2",
        "status" : "skipped",
        "statusDetails" : "XFAIL reason: Known server-side issue\n\n_pytest.outcomes.XFailed: Known server-side issue",
        "time" : {
          "start" : 1704839546391,
          "stop" : 1704839547678,
          "duration" : 1287
        }
      }, {
        "uid" : "8b2995c1d1a4e4b5",
        "status" : "skipped",
        "statusDetails" : "XFAIL reason: Known server-side issue\n\n_pytest.outcomes.XFailed: Known server-side issue",
        "time" : {
          "start" : 1704789360100,
          "stop" : 1704789361271,
          "duration" : 1171
        }
      }, {
        "uid" : "e0e21325e73abf2c",
        "status" : "skipped",
        "statusDetails" : "XFAIL reason: Known server-side issue\n\n_pytest.outcomes.XFailed: Known server-side issue",
        "time" : {
          "start" : 1704759030280,
          "stop" : 1704759031332,
          "duration" : 1052
        }
      }, {
        "uid" : "5e4d1b792a3fc697",
        "status" : "skipped",
        "statusDetails" : "XFAIL reason: Known server-side issue\n\n_pytest.outcomes.XFailed: Known server-side issue",
        "time" : {
          "start" : 1704756570957,
          "stop" : 1704756572424,
          "duration" : 1467
        }
      } ]
    },
    "tags" : [ ]
  },
  "source" : "8b9cb9084df2ea16.json",
  "parameterValues" : [ ]
}