{
  "uid" : "e04b62efc34bb97d",
  "name" : "User can't successfully log in with invalid password.",
  "fullName" : "tests.core_features.test_login.TestLogin#test_login_with_invalid_password",
  "historyId" : "0ca18d8bd97e96e2fad3ec13e04117a8",
  "time" : {
    "start" : 1704913007085,
    "stop" : 1704913007821,
    "duration" : 736
  },
  "status" : "skipped",
  "statusMessage" : "XFAIL reason: Known server-side issue\n\n_pytest.outcomes.XFailed: Known server-side issue",
  "statusTrace" : "tests/core_features/test_login.py:50: in test_login_with_invalid_password\n    login_page.error_text.assert_error(\"The username and password could not be verified.\")\n        driver     = <selenium.webdriver.chrome.webdriver.WebDriver (session=\"47034f35cad18d62c7e66b936ce88af8\")>\n        home_page  = <src.pages.home_page.HomePage object at 0x7f3f573a1c50>\n        login_page = <src.pages.login_page.LoginPage object at 0x7f3f573bf050>\n        self       = <test_login.TestLogin object at 0x7f3f573df550>\nsrc/base/base_element.py:71: in assert_error\n    pytest.xfail(reason=\"Known server-side issue\")\nE   _pytest.outcomes.XFailed: Known server-side issue\n        current_error = 'An internal error has occurred and has been logged.'\n        expected_error = 'The username and password could not be verified.'\n        self       = <src.base.base_element.BaseElement object at 0x7f3f573a1050>\n        server_error = 'An internal error has occurred and has been logged.'",
  "flaky" : false,
  "newFailed" : false,
  "beforeStages" : [ {
    "name" : "Initialize driver",
    "time" : {
      "start" : 1704913006246,
      "stop" : 1704913007084,
      "duration" : 838
    },
    "status" : "passed",
    "steps" : [ ],
    "attachments" : [ ],
    "parameters" : [ ],
    "attachmentsCount" : 0,
    "shouldDisplayMessage" : false,
    "stepsCount" : 0,
    "hasContent" : false
  }, {
    "name" : "_session_faker",
    "time" : {
      "start" : 1704912932040,
      "stop" : 1704912932061,
      "duration" : 21
    },
    "status" : "passed",
    "steps" : [ ],
    "attachments" : [ ],
    "parameters" : [ ],
    "attachmentsCount" : 0,
    "shouldDisplayMessage" : false,
    "stepsCount" : 0,
    "hasContent" : false
  }, {
    "name" : "Health check request",
    "time" : {
      "start" : 1704912932061,
      "stop" : 1704912932272,
      "duration" : 211
    },
    "status" : "passed",
    "steps" : [ ],
    "attachments" : [ ],
    "parameters" : [ ],
    "attachmentsCount" : 0,
    "shouldDisplayMessage" : false,
    "stepsCount" : 0,
    "hasContent" : false
  } ],
  "testStage" : {
    "status" : "skipped",
    "statusMessage" : "XFAIL reason: Known server-side issue\n\n_pytest.outcomes.XFailed: Known server-side issue",
    "statusTrace" : "tests/core_features/test_login.py:50: in test_login_with_invalid_password\n    login_page.error_text.assert_error(\"The username and password could not be verified.\")\n        driver     = <selenium.webdriver.chrome.webdriver.WebDriver (session=\"47034f35cad18d62c7e66b936ce88af8\")>\n        home_page  = <src.pages.home_page.HomePage object at 0x7f3f573a1c50>\n        login_page = <src.pages.login_page.LoginPage object at 0x7f3f573bf050>\n        self       = <test_login.TestLogin object at 0x7f3f573df550>\nsrc/base/base_element.py:71: in assert_error\n    pytest.xfail(reason=\"Known server-side issue\")\nE   _pytest.outcomes.XFailed: Known server-side issue\n        current_error = 'An internal error has occurred and has been logged.'\n        expected_error = 'The username and password could not be verified.'\n        self       = <src.base.base_element.BaseElement object at 0x7f3f573a1050>\n        server_error = 'An internal error has occurred and has been logged.'",
    "steps" : [ {
      "name" : "Navigate to Home page",
      "time" : {
        "start" : 1704913007085,
        "stop" : 1704913007323,
        "duration" : 238
      },
      "status" : "passed",
      "steps" : [ ],
      "attachments" : [ ],
      "parameters" : [ ],
      "attachmentsCount" : 0,
      "shouldDisplayMessage" : false,
      "stepsCount" : 0,
      "hasContent" : false
    }, {
      "name" : "Fill in valid username, but invalid password",
      "time" : {
        "start" : 1704913007323,
        "stop" : 1704913007483,
        "duration" : 160
      },
      "status" : "passed",
      "steps" : [ ],
      "attachments" : [ ],
      "parameters" : [ ],
      "attachmentsCount" : 0,
      "shouldDisplayMessage" : false,
      "stepsCount" : 0,
      "hasContent" : false
    }, {
      "name" : "Log in",
      "time" : {
        "start" : 1704913007483,
        "stop" : 1704913007734,
        "duration" : 251
      },
      "status" : "passed",
      "steps" : [ ],
      "attachments" : [ ],
      "parameters" : [ ],
      "attachmentsCount" : 0,
      "shouldDisplayMessage" : false,
      "stepsCount" : 0,
      "hasContent" : false
    }, {
      "name" : "Check error message is displayed",
      "time" : {
        "start" : 1704913007734,
        "stop" : 1704913007820,
        "duration" : 86
      },
      "status" : "failed",
      "statusMessage" : "_pytest.outcomes.XFailed: Known server-side issue\n",
      "statusTrace" : "  File \"/usr/workspace/tests/core_features/test_login.py\", line 50, in test_login_with_invalid_password\n    login_page.error_text.assert_error(\"The username and password could not be verified.\")\n  File \"/usr/workspace/src/base/base_element.py\", line 71, in assert_error\n    pytest.xfail(reason=\"Known server-side issue\")\n  File \"/usr/local/lib/python3.11/site-packages/_pytest/outcomes.py\", line 256, in xfail\n    raise XFailed(reason)\n",
      "steps" : [ ],
      "attachments" : [ ],
      "parameters" : [ ],
      "attachmentsCount" : 0,
      "shouldDisplayMessage" : true,
      "stepsCount" : 0,
      "hasContent" : true
    } ],
    "attachments" : [ ],
    "parameters" : [ ],
    "attachmentsCount" : 0,
    "shouldDisplayMessage" : true,
    "stepsCount" : 4,
    "hasContent" : true
  },
  "afterStages" : [ {
    "name" : "Initialize driver::0",
    "time" : {
      "start" : 1704913007859,
      "stop" : 1704913007915,
      "duration" : 56
    },
    "status" : "passed",
    "steps" : [ {
      "name" : "Terminate driver",
      "time" : {
        "start" : 1704913007859,
        "stop" : 1704913007915,
        "duration" : 56
      },
      "status" : "passed",
      "steps" : [ ],
      "attachments" : [ ],
      "parameters" : [ ],
      "attachmentsCount" : 0,
      "shouldDisplayMessage" : false,
      "stepsCount" : 0,
      "hasContent" : false
    } ],
    "attachments" : [ ],
    "parameters" : [ ],
    "attachmentsCount" : 0,
    "shouldDisplayMessage" : false,
    "stepsCount" : 1,
    "hasContent" : true
  } ],
  "labels" : [ {
    "name" : "epic",
    "value" : "PARA-15240: User registration and authentication"
  }, {
    "name" : "severity",
    "value" : "Minor"
  }, {
    "name" : "feature",
    "value" : "PARA-15261: User login"
  }, {
    "name" : "parentSuite",
    "value" : "tests.core_features"
  }, {
    "name" : "suite",
    "value" : "test_login"
  }, {
    "name" : "subSuite",
    "value" : "TestLogin"
  }, {
    "name" : "host",
    "value" : "eb65c548bdd0"
  }, {
    "name" : "thread",
    "value" : "1-MainThread"
  }, {
    "name" : "framework",
    "value" : "pytest"
  }, {
    "name" : "language",
    "value" : "cpython3"
  }, {
    "name" : "package",
    "value" : "tests.core_features.test_login"
  }, {
    "name" : "resultFormat",
    "value" : "allure2"
  } ],
  "parameters" : [ ],
  "links" : [ ],
  "hidden" : false,
  "retry" : false,
  "extra" : {
    "severity" : "minor",
    "retries" : [ ],
    "categories" : [ ],
    "history" : {
      "statistic" : {
        "failed" : 0,
        "broken" : 0,
        "skipped" : 7,
        "passed" : 0,
        "unknown" : 0,
        "total" : 7
      },
      "items" : [ {
        "uid" : "34036144644cbdca",
        "status" : "skipped",
        "statusDetails" : "XFAIL reason: Health check failed with status code 502\n\n_pytest.outcomes.XFailed: Health check failed with status code 502",
        "time" : {
          "start" : 1704908682724,
          "stop" : 1704908682724,
          "duration" : 0
        }
      }, {
        "uid" : "bf6294b63c28caed",
        "status" : "skipped",
        "statusDetails" : "XFAIL reason: Known server-side issue\n\n_pytest.outcomes.XFailed: Known server-side issue",
        "time" : {
          "start" : 1704874970180,
          "stop" : 1704874971491,
          "duration" : 1311
        }
      }, {
        "uid" : "d87ec95d2bd7a1d7",
        "status" : "skipped",
        "statusDetails" : "XFAIL reason: Known server-side issue\n\n_pytest.outcomes.XFailed: Known server-side issue",
        "time" : {
          "start" : 1704839544422,
          "stop" : 1704839545491,
          "duration" : 1069
        }
      }, {
        "uid" : "ceab7a397b75762c",
        "status" : "skipped",
        "statusDetails" : "XFAIL reason: Known server-side issue\n\n_pytest.outcomes.XFailed: Known server-side issue",
        "time" : {
          "start" : 1704789358098,
          "stop" : 1704789359199,
          "duration" : 1101
        }
      }, {
        "uid" : "bb142fe10b5e53ec",
        "status" : "skipped",
        "statusDetails" : "XFAIL reason: Known server-side issue\n\n_pytest.outcomes.XFailed: Known server-side issue",
        "time" : {
          "start" : 1704759028518,
          "stop" : 1704759029330,
          "duration" : 812
        }
      }, {
        "uid" : "cce9cde06874d2bf",
        "status" : "skipped",
        "statusDetails" : "XFAIL reason: Known server-side issue\n\n_pytest.outcomes.XFailed: Known server-side issue",
        "time" : {
          "start" : 1704756568705,
          "stop" : 1704756570047,
          "duration" : 1342
        }
      } ]
    },
    "tags" : [ ]
  },
  "source" : "e04b62efc34bb97d.json",
  "parameterValues" : [ ]
}